<mujoco model="elbow_exoskeleton">
  <compiler angle="degree" coordinate="local" inertiafromgeom="true"/>
  
  <option timestep="0.002" integrator="RK4"/>
  
  <default>
    <joint armature="0.1" damping="0.1" limited="true"/>
    <geom conaffinity="0" contype="0" density="5.0" friction="1 0.5 0.005" rgba="0.8 0.6 0.4 1"/>
    <motor ctrllimited="true" ctrlrange="-10 10"/>
  </default>
  
  <asset>
    <texture builtin="gradient" height="100" rgb1="1 1 1" rgb2="0 0 0" type="skybox" width="100"/>
    <texture builtin="flat" height="1278" mark="cross" markrgb="1 1 1" name="texgeom" random="0.01" rgb1="0.8 0.6 0.4" rgb2="0.8 0.6 0.4" type="cube" width="127"/>
    <texture builtin="checker" height="100" name="texplane" rgb1="0 0 0" rgb2="0.8 0.8 0.8" type="2d" width="100"/>
    <material name="MatPlane" reflectance="0.5" shininess="1" specular="1" texrepeat="60 60" texture="texplane"/>
    <material name="geom" texture="texgeom" texuniform="true"/>
  </asset>
  
  <worldbody>
    <light cutoff="100" diffuse="1 1 1" dir="-0 0 -1.3" directional="true" exponent="1" pos="0 0 1.3" specular=".1 .1 .1"/>
    <geom conaffinity="1" condim="3" material="MatPlane" name="floor" pos="0 0 0" rgba="0.8 0.9 0.8 1" size="40 40 40" type="plane"/>
    
    <!-- Base/Shoulder Mount -->
    <body name="base" pos="0 0 1">
      <geom name="base_geom" type="cylinder" size="0.05 0.1" rgba="0.3 0.3 0.3 1"/>
      
      <!-- Upper Arm -->
      <body name="upper_arm" pos="0 0 0.1">
        <joint name="shoulder_joint" type="hinge" axis="0 1 0" range="-45 135" pos="0 0 0"/>
        <geom name="upper_arm_geom" type="capsule" size="0.03" fromto="0 0 0 0 0 -0.3" rgba="0.2 0.6 0.8 1"/>
        
        <!-- Forearm -->
        <body name="forearm" pos="0 0 -0.3">
          <joint name="elbow_joint" type="hinge" axis="0 1 0" range="0 150" pos="0 0 0"/>
          <geom name="forearm_geom" type="capsule" size="0.025" fromto="0 0 0 0 0 -0.25" rgba="0.8 0.4 0.2 1"/>
          
          <!-- Hand/End Effector -->
          <body name="hand" pos="0 0 -0.25">
            <geom name="hand_geom" type="sphere" size="0.04" rgba="0.6 0.8 0.2 1"/>
          </body>
        </body>
      </body>
    </body>
    
    <!-- Target position indicator -->
    <body name="target" pos="0.4 0 0.8">
      <geom name="target_geom" type="sphere" size="0.03" rgba="1 0 0 0.5" contype="0" conaffinity="0"/>
    </body>
  </worldbody>
  
  <actuator>
    <motor name="shoulder_motor" joint="shoulder_joint" gear="10"/>
    <motor name="elbow_motor" joint="elbow_joint" gear="10"/>
  </actuator>
  
  <sensor>
    <jointpos name="shoulder_pos" joint="shoulder_joint"/>
    <jointvel name="shoulder_vel" joint="shoulder_joint"/>
    <jointpos name="elbow_pos" joint="elbow_joint"/>
    <jointvel name="elbow_vel" joint="elbow_joint"/>
    <actuatorfrc name="shoulder_torque" actuator="shoulder_motor"/>
    <actuatorfrc name="elbow_torque" actuator="elbow_motor"/>
  </sensor>
</mujoco>